Workbook

Sheet Hoja1
A1: Nombre | B1: 1-set 570-Bº 40 Viviendas - Rebagliatti | C1: 2-set438-Francia E Hilario Lagos | D1: 3-set509-Borges y Lima Quintana | E1: 4-set26-Brasil e Hilario Lagos | F1: 5-set279-Mexico y Rep. Dominicana | G1: 6-set386-Paraguay y Mexico | H1: 7-set405-el salvador e/ Ecuador y surigan | I1: 8-set579-Tristan Lobos y Peru | J1: 9-set608 J. HERNANDEZ Y G. PAZ | K1: 10-set17-T. Lobos y Hernandez | L1: 11-set 25 Metrive - Av. antartida | M1: 12-set439 Colombia e/ Brasil y Fransisco Maglioti | N1: 13-set147 Ceibo america | O1: 14-set80 Av antartida y croacia SUPERMERCADO L Y L | P1: 15-set 290-Ortelli y Filippone | Q1: 16-Set5 De los inmigrantes y croacia | R1: 17-set229-T. Lobos y Filipone | S1: 18-set6-B. Voluntarios Y R. Escalada | T1: 19-set 521-Bomberos voluntarios y venezuela | U1: 20-set 10-Croacia y Pelliza | V1: 21-set357-España Y Pueyrredon | W1: 22- | X1: 23 | Y1: 24
A2: SET | B2: 570 | C2: 438 | D2: 509 | E2: 26 | F2: 279 | G2: 386 | H2: 405 | I2: 579 | J2: 608 | K2: 17 | L2: 25 | M2: 439 | N2: 147 | O2: 80 | P2: 290 | Q2: 5 | R2: 229 | S2: 6 | T2: 521 | U2: 10 | V2: 357
A3: IP | B3: 192.168.20.44 | C3: 192.168.20.42 | D3: 192.168.20.61 | E3: 192.168.20.59 | F3: 192.168.20.56 | G3: 192.168.20.57 | H3: 192.168.20.58 | I3: 192.168.20.55 | J3: 192.168.20.60 | K3: 192.168.20.22 | L3: 192.168.20.66 | M3: 192.168.20.81 | N3: 172.16.20.70 | O3: 192.168.20.65 | P3: 192.168.20.54 | Q3: 172.16.10.33 | R3: 192.168.20.33 | S3: 192.168.20.36 | T3: 172.16.0.121 | U3: 192.168.20.50 | V3: 192.168.20.39 | Y3: 186.56.57.94
B4: 105 | C4: 130 | D4: 101 | E4: 233 | F4: 141 | G4: 37 | H4: 107 | I4: 103 | J4: 115 | K4: 223 | L4: 70 | M4: 65 | N4: 66 | O4: 66 | P4: 180 | Q4: 256 | R4: 183 | S4: 233 | T4: 95 | U4: 96 | V4: 119 | AA4: 2724 | AB4: 2750 | AC4: 26
B5: 10 | C5: 26 | D5: 4 | E5: 18 | F5: 3 | G5: 3 | H5: 10 | I5: 4 | J5: 3 | K5: 32 | L5: 19 | M5: 10 | N5: 11 | O5: 18 | P5: 21 | Q5: 38 | R5: 18 | S5: 35 | T5: 4 | U5: 7 | V5: 0 | AA5: 294
B6: 95 | C6: 104 | D6: 97 | E6: 215 | F6: 138 | G6: 34 | H6: 97 | I6: 99 | J6: 112 | K6: 191 | L6: 51 | M6: 55 | N6: 55 | O6: 48 | P6: 159 | Q6: 218 | R6: 165 | S6: 198 | T6: 91 | U6: 89 | V6: 119 | AA6: 2430
B7: Ruta12 | C7: Ruta16 | D7: Ruta16 | E7: Ruta16 | F7: Ruta15 | G7: Ruta15 | H7: Ruta15 | I7: Ruta15 | J7: Ruta15 | K7: Ruta15 | L7: Ruta15 | M7: Ruta16 | N7: Ruta16 | O7: Ruta 16/5 | AA7: 2480
A8: Ruta | B8: 1570 | C8: 1438 | D8: 1509 | E8: 1026 | F8: 1279 | G8: 1386 | H8: 1405 | I8: 1579 | J8: 1608 | K8: 1017 | L8: 1025 | M8: 1439 | N8: 1147 | O8: 1080 | P8: 1290 | Q8: 1005 | R8: 1229 | AA8: 50
A9: Concentradores | B9: 4621502023 | C9: 4621606418 | D9: 4621502009 | E9: 4621936100 | F9: 4621838101 | G9: 4622004200 | H9: 4622004205 | I9: 4622004210 | J9: 4622004173 | K9: 4621936122 | L9: 4622004201 | M9: 4621936101 | N9: 4622004203 | O9: 4622050030 | P9: 4622004164 | Q9: 4622050035 | R9: 4622050048 | S9: 4622103050 | T9: 4621606418 | U9: 4622103037 | V9: 4622103053
A10: medidores | B10: 141825570 | C10: 141825620 | D10: 141906147 | E10: 141911187 | F10: 141911424 | G10: 141911454 | H10: 141914312 | I10: 141911451 | J10: 141911564 | K10: 141825649 | L10: 142002057 | M10: 141911579 | N10: 142002997 | O10: 141911585 | P10: 141911586 | Q10: 141906939 | R10: 141914832 | S10: 141914548 | T10: 141914882 | U10: 141915014 | V10: 141914793
B11: 141825571 | C11: 141825621 | D11: 141906868 | E11: 141911199 | F11: 141911425 | G11: 141911455 | H11: 141914313 | I11: 141911452 | J11: 141914426 | K11: 141911564 | L11: 142002058 | M11: 141911580 | N11: 142002998 | O11: 141911588 | P11: 142002234 | Q11: 141915078 | R11: 141914833 | S11: 141914792 | T11: 141914889 | U11: 141915018 | V11: 141914794
B12: 141825572 | C12: 141825622 | D12: 141906869 | E12: 141911200 | F12: 141911426 | G12: 141911456 | H12: 141914314 | I12: 141911453 | J12: 141914428 | K12: 141911658 | L12: 142002059 | M12: 141911581 | N12: 142002999 | O12: 141911589 | P12: 142002808 | Q12: 142002047 | R12: 141914834 | S12: 141914982 | T12: 141914930 | U12: 141915019 | V12: 141914795
B13: 141825573 | C13: 141825623 | D13: 141906870 | E13: 141911201 | F13: 141911427 | G13: 141911457 | H13: 141914315 | I13: 141911459 | J13: 141914429 | K13: 141911676 | L13: 142002060 | M13: 141911583 | N13: 142003000 | O13: 141911590 | P13: 142002809 | Q13: 142002048 | R13: 141914835 | S13: 141914983 | T13: 141915705 | U13: 141915033 | V13: 141914796
B14: 141825574 | C14: 141825624 | D14: 141906871 | E14: 141911202 | F14: 141911428 | G14: 141911458 | H14: 141914316 | I14: 141911504 | J14: 141914431 | K14: 141914351 | L14: 142002061 | M14: 141911584 | N14: 142003001 | O14: 141911591 | P14: 142003677 | Q14: 142002051 | R14: 141914836 | S14: 141914984 | T14: 141915706 | U14: 142002236 | V14: 141914798
B15: 141825575 | C15: 141825625 | D15: 141906872 | E15: 141911204 | F15: 141911429 | G15: 141911460 | H15: 141914317 | I15: 141911505 | J15: 141914432 | K15: 141914356 | L15: 142002062 | M15: 141914486 | N15: 142003002 | O15: 141911592 | P15: 142003678 | Q15: 142002053 | R15: 141914837 | S15: 141914985 | T15: 141915708 | U15: 142003577 | V15: 141914799
B16: 141825576 | C16: 141825626 | D16: 141906873 | E16: 141911205 | F16: 141911430 | G16: 141911484 | H16: 141914318 | I16: 141911506 | J16: 141914433 | K16: 141914358 | L16: 142002063 | M16: 142002107 | N16: 142003003 | O16: 141911594 | P16: 142003679 | Q16: 142002056 | R16: 141914838 | S16: 141914986 | T16: 141915709 | U16: 142003578 | V16: 141914800
B17: 141825577 | C17: 141825627 | D17: 141906874 | E17: 141911206 | F17: 141911431 | G17: 141911485 | H17: 141914319 | I17: 141911509 | J17: 141914434 | K17: 141914359 | L17: 142002064 | M17: 142002108 | N17: 142003004 | O17: 141911595 | P17: 142003680 | Q17: 142002230 | R17: 141914839 | S17: 141914987 | T17: 141915711 | U17: 142003579 | V17: 141914801
B18: 141825578 | C18: 141825628 | D18: 141906875 | E18: 141911209 | F18: 141911432 | G18: 141911486 | H18: 141914320 | I18: 141911510 | J18: 141914436 | K18: 141914360 | L18: 142002065 | M18: 142002109 | N18: 142003005 | O18: 141911596 | P18: 142003681 | Q18: 142002445 | R18: 141914840 | S18: 141914988 | T18: 142001915 | U18: 142003580 | V18: 141915162
B19: 141825579 | C19: 141825629 | D19: 141906876 | E19: 141911210 | F19: 141911433 | G19: 141911491 | H19: 141914321 | I19: 141911512 | J19: 141914437 | K19: 141914361 | L19: 142002066 | M19: 142002110 | N19: 142003006 | O19: 141911597 | P19: 142003682 | Q19: 142003357 | R19: 141914841 | S19: 141914989 | T19: 142001916 | U19: 142003581 | V19: 141915163
B20: 141825580 | C20: 141825630 | D20: 141906877 | E20: 141911214 | F20: 141911434 | G20: 141911492 | H20: 141914322 | I20: 141914882 | J20: 141914438 | K20: 141914362 | L20: 142002067 | M20: 142002111 | N20: 142003007 | O20: 141911598 | P20: 142003683 | Q20: 142003358 | R20: 141914842 | S20: 141914990 | T20: 142001927 | U20: 142003582 | V20: 141915164
B21: 141825581 | C21: 141825631 | D21: 141906880 | E21: 141911215 | F21: 141911435 | G21: 141911493 | H21: 141914323 | I21: 142001867 | J21: 141914439 | K21: 141914363 | L21: 142002068 | M21: 142002112 | N21: 142003008 | O21: 141911599 | P21: 142003684 | Q21: 142003359 | R21: 141914843 | S21: 141914991 | T21: 142008915 | U21: 142003583 | V21: 141915165
B22: 141825582 | C22: 141825632 | D22: 141906881 | E22: 141911216 | F22: 141911436 | G22: 141911522 | H22: 141914324 | I22: 142001868 | J22: 141914440 | K22: 141914364 | L22: 142002069 | M22: 142002113 | N22: 142003009 | O22: 141911600 | P22: 142003685 | Q22: 142003360 | R22: 141914844 | S22: 141914992 | T22: 142008916 | U22: 142003584 | V22: 141915166
... B72: 141906140 | C72: 141911186 | D72: 141906934 | E72: 141911266 | F72: 141911508 | G72: 502003239 | H72: 142001557 | I72: 142001922 | J72: 142001999 | K72: 141914416 | L72: 501916058 | M72: 142003849 | N72: 501916112 | O72: 502003244 | P72: 142003735 | Q72: 142003412 | R72: 141914895 | S72: 141915045 | T72: 142008966 | U72: 142008348 | V72: 142002801
B73: 141906141 | C73: 141911188 | D73: 141906935 | E73: 141911267 | F73: 141911511 | H73: 142001558 | I73: 142001923 | J73: 142002000 | K73: 141914417 | L73: 501916059 | M73: 501821909 | N73: 501916113 | O73: 502003245 | P73: 142003736 | Q73: 142003413 | R73: 141914896 | S73: 141915046 | T73: 142008967 | U73: 142008349 | V73: 142002802
B74: 141906142 | C74: 141911189 | D74: 141906936 | E74: 141911268 | F74: 141911513 | H74: 142001559 | I74: 142001924 | J74: 142002001 | K74: 141914418 | L74: 501916060 | M74: 501916063 | N74: 501916114 | O74: 502003246 | P74: 142003737 | Q74: 142003414 | R74: 141914897 | S74: 141915047 | T74: 142008968 | U74: 142008350 | V74: 142002803
B75: 141906145 | C75: 141911190 | D75: 141906937 | E75: 141911269 | F75: 141911514 | H75: 142001560 | I75: 142001925 | J75: 142002002 | K75: 141914419 | L75: 501916061 | N75: 502003243 | O75: 502003247 | P75: 142003738 | Q75: 142003415 | R75: 141914898 | S75: 141915048 | T75: 142008969 | U75: 142008351 | V75: 142002804
B76: 141906146 | C76: 141911191 | D76: 141906938 | E76: 141911270 | F76: 141911515 | H76: 142001561 | I76: 142001926 | J76: 142002004 | K76: 141914420 | L76: 501916062 | P76: 142003739 | Q76: 142003416 | R76: 141914899 | S76: 141915049 | T76: 142008970 | U76: 142008352 | V76: 142002805
B77: 141906178 | C77: 141911192 | D77: 141906940 | E77: 141911271 | F77: 141911516 | H77: 142001562 | I77: 142001928 | J77: 142002005 | K77: 141914421 | L77: 502003092 | P77: 142003740 | Q77: 142003417 | R77: 141914900 | S77: 141915050 | T77: 142008971 | U77: 142008353 | V77: 142002806
B78: 141906179 | C78: 141911193 | D78: 141906941 | E78: 141911272 | F78: 141911517 | H78: 142001563 | I78: 142001929 | J78: 142002006 | K78: 141914422 | L78: 502003197 | P78: 142003741 | Q78: 142003418 | R78: 141914901 | S78: 141915051 | T78: 142008972 | U78: 142008354 | V78: 142003337
B79: 141906180 | C79: 141911194 | D79: 141906942 | E79: 141911273 | F79: 141911518 | H79: 142001564 | I79: 142001930 | J79: 142002007 | K79: 141914423 | L79: 502003243 | P79: 142003742 | Q79: 142003419 | R79: 141914902 | S79: 141915052 | T79: 142008973 | U79: 142008655 | V79: 142003338
B80: 141906181 | C80: 141911195 | D80: 141906943 | E80: 141911274 | F80: 141911519 | H80: 142001565 | I80: 142001931 | J80: 142002008 | K80: 141914424 | P80: 142003743 | Q80: 142003420 | R80: 141914903 | S80: 141915053 | T80: 142008974 | U80: 142008656 | V80: 142003339
B81: 141906182 | C81: 141911196 | D81: 141906944 | E81: 141911275 | F81: 141911520 | H81: 142001566 | I81: 142001933 | J81: 142002009 | K81: 141914425 | P81: 142003744 | Q81: 142003421 | R81: 141914904 | S81: 141915054 | T81: 142008975 | U81: 142008657 | V81: 142003340
B82: 141906183 | C82: 141911197 | D82: 141906945 | E82: 141911276 | F82: 141911521 | H82: 142001567 | I82: 142001934 | J82: 142002010 | K82: 141914427 | P82: 142003745 | Q82: 142003422 | R82: 141914905 | S82: 141915055 | T82: 142008976 | U82: 142008658 | V82: 142003341
B83: 141906184 | C83: 141911198 | D83: 141906946 | E83: 141911277 | F83: 141911523 | H83: 142001568 | I83: 142001935 | J83: 142002011 | K83: 141914435 | P83: 142003746 | Q83: 142003423 | R83: 141914906 | S83: 141915056 | T83: 142008977 | U83: 142008659 | V83: 142003342
B84: 141906185 | C84: 141911203 | D84: 141906947 | E84: 141911279 | F84: 141911524 | H84: 142001569 | I84: 142001937 | J84: 142002012 | K84: 141914442 | P84: 142003747 | Q84: 142003424 | R84: 141914907 | S84: 141915057 | T84: 142008978 | U84: 142008660 | V84: 142003343
B85: 141906186 | C85: 141911207 | D85: 141906948 | E85: 141911280 | F85: 141911525 | H85: 142001570 | I85: 142001938 | J85: 142002013 | K85: 141914443 | P85: 142003748 | Q85: 142003425 | R85: 141914908 | S85: 141915058 | T85: 142008979 | U85: 142008661 | V85: 142003344
B86: 141906187 | C86: 141911208 | D86: 141906949 | E86: 141911281 | F86: 141911526 | H86: 142001571 | I86: 142001939 | J86: 142002014 | K86: 141914444 | P86: 142003749 | Q86: 142003426 | R86: 141914909 | S86: 141915059 | T86: 142008980 | U86: 142008662 | V86: 142003345
B87: 141911278 | C87: 141911211 | D87: 141906950 | E87: 141911282 | F87: 141911527 | H87: 142001572 | I87: 142001940 | J87: 142002015 | K87: 141914445 | P87: 142003750 | Q87: 142003427 | R87: 141914910 | S87: 141915060 | T87: 142008981 | U87: 142008663 | V87: 142003346
B88: 141911418 | C88: 141911212 | D88: 141906951 | E88: 141911283 | F88: 141911529 | H88: 142001573 | I88: 142001941 | J88: 142002016 | K88: 141914446 | P88: 142003751 | Q88: 142003428 | R88: 141914911 | S88: 141915061 | T88: 142008982 | U88: 142008664 | V88: 142003347
B89: 141911423 | C89: 141911213 | D89: 141906952 | E89: 141911284 | F89: 141911530 | H89: 142001574 | I89: 142001942 | J89: 142002017 | K89: 141914447 | P89: 142003752 | Q89: 142003429 | R89: 141914912 | S89: 141915062 | T89: 142008983 | U89: 142008665 | V89: 142003348
...

Sheet Hoja1-1
A1: Nombre | B1: 1-set 570-Bº 40 Viviendas - Rebagliatti | C1: 2-set438-Francia E Hilario Lagos | D1: 3-set509-Borges y Lima Quintana | E1: 4-set26-Brasil e Hilario Lagos | F1: 5-set279-Mexico y Rep. Dominicana | G1: 6-set386-Paraguay y Mexico | H1: 7-set405-el salvador e/ Ecuador y surigan | I1: 8-set579-Tristan Lobos y Peru | J1: 9-set608 J. HERNANDEZ Y G. PAZ | K1: 10-set17-T. Lobos y Hernandez | L1: 11-set 25 Metrive - Av. antartida | M1: 12-set439 Colombia e/ Brasil y Fransisco Maglioti | N1: 13-set147 Ceibo america | O1: 14-set80 Av antartida y croacia SUPERMERCADO L Y L | P1: 15-set 290-Ortelli y Filippone | Q1: 16-Set5 De los inmigrantes y croacia | R1: 17-set229-T. Lobos y Filipone | S1: 18-set6-B. Voluntarios Y R. Escalada | T1: 19-set 521-Bomberos voluntarios y venezuela | U1: 20-set 10-Croacia y Pelliza | V1: 21-set357-España Y Pueyrredon
A2: SET | B2: 570 | C2: 438 | D2: 509 | E2: 26 | F2: 279 | G2: 386 | H2: 405 | I2: 579 | J2: 608 | K2: 17 | L2: 25 | M2: 439 | N2: 147 | O2: 80 | P2: 290 | Q2: 5 | R2: 229 | S2: 6 | T2: 521 | U2: 10 | V2: 357
A3: IP | B3: 192.168.20.44 | C3: http://192.168.20.42 | D3: http://192.168.20.61 | E3: http://192.168.20.59 | F3: http://192.168.20.56 | G3: http://192.168.20.57 | H3: http://192.168.20.58 | I3: http://192.168.20.55 | J3: http://192.168.20.60 | K3: http://192.168.20.22 | L3: http://192.168.20.66 | M3: http://192.168.20.81 | N3: http://172.16.20.70 | O3: http://192.168.20.65 | P3: http://192.168.20.54 | Q3: http://172.16.10.33 | R3: http://192.168.20.33 | S3: http://192.168.20.36 | T3: http://172.16.0.121 | U3: http://192.168.20.50/ | V3: http://192.168.20.39/
B4: =105 -> 105 | C4: 130 | D4: 101 | E4: 233 | F4: =141 -> 141 | G4: =37 -> 37 | H4: 107 | I4: =103 -> 103 | J4: 115 | K4: 223 | L4: 70 | M4: 65 | N4: 66 | O4: 66 | P4: 180 | Q4: 256 | R4: 183 | S4: 233 | T4: 95 | U4: 96 | V4: 119 | X4: =SUM(B4:W4) -> 2724 | Y4: 2750 | Z4: =Y4-X4 -> 26
B5: 10 | C5: 26 | D5: 4 | E5: 18 | F5: 3 | G5: 3 | H5: 10 | I5: 4 | J5: 3 | K5: 32 | L5: 19 | M5: 10 | N5: 11 | O5: 18 | P5: 21 | Q5: 38 | R5: 18 | S5: 35 | T5: 4 | U5: 7 | V5: 0 | X5: =SUM(B5:W5) -> 294
B6: =B4-B5 -> 95 | C6: =C4-C5 -> 104 | D6: =D4-D5 -> 97 | E6: =E4-E5 -> 215 | F6: =F4-F5 -> 138 | G6: =G4-G5 -> 34 | H6: =H4-H5 -> 97 | I6: =I4-I5 -> 99 | ... V6: =V4-V5 -> 119 | X6: =SUM(B6:W6) -> 2430
B7: Ruta12 | C7: Ruta16 | D7: Ruta16 | E7: Ruta16 | F7: Ruta15 | G7: Ruta15 | H7: Ruta15 | I7: Ruta15 | J7: Ruta15 | K7: Ruta15 | L7: Ruta15 | M7: Ruta16 | N7: Ruta16 | O7: Ruta 16/5 | X7: 2480
A8: Ruta | B8: 1570 | C8: 1438 | D8: 1509 | E8: 1026 | F8: 1279 | G8: 1386 | H8: 1405 | I8: 1579 | J8: 1608 | K8: 1017 | L8: 1025 | M8: 1439 | N8: 1147 | O8: 1080 | P8: 1290 | Q8: 1005 | R8: 1229 | X8: =X7-X6 -> 50
A9: Concentradores | B9: 4621502023 | C9: 4621606418 | D9: 4621502009 | E9: 4621936100 | F9: 4621838101 | G9: 4622004200 | H9: 4622004205 | I9: 4622004210 | J9: 4622004173 | K9: 4621936122 | L9: 4622004201 | M9: 4621936101 | N9: 4622004203 | O9: 4622050030 | R9: 4622050048 | S9: 4622103050 | U9: 4622103037 | V9: 4622103053
A10: medidores | B10: 141825570 | C10: 141825620 | D10: 141906147 | E10: 141911187 | F10: 141911424 | G10: 141911454 | H10: 141914312 | I10: 141911451 | J10: 141911564 | K10: 141825649 | L10: 142002057 | M10: 141911579 | N10: 142002997 | O10: 141911585 | P10: 141911586 | Q10: 141906939 | R10: 141914832 | S10: 141914548 | T10: 141914882 | U10: 141915014 | V10: 141914793
B11: 141825571 | C11: 141825621 | D11: 141906868 | E11: 141911199 | F11: 141911425 | G11: 141911455 | H11: 141914313 | I11: 141911452 | J11: 141914426 | K11: 141911564 | L11: 142002058 | M11: 141911580 | N11: 142002998 | O11: 141911588 | P11: 142002234 | Q11: 141915078 | R11: 141914833 | S11: 141914792 | T11: 141914889 | U11: 141915018 | V11: 141914794
B12: 141825572 | C12: 141825622 | D12: 141906869 | E12: 141911200 | F12: 141911426 | G12: 141911456 | H12: 141914314 | I12: 141911453 | J12: 141914428 | K12: 141911658 | L12: 142002059 | M12: 141911581 | N12: 142002999 | O12: 141911589 | P12: 142002808 | Q12: 142002047 | R12: 141914834 | S12: 141914982 | T12: 141914930 | U12: 141915019 | V12: 141914795
B13: 141825573 | C13: 141825623 | D13: 141906870 | E13: 141911201 | F13: 141911427 | G13: 141911457 | H13: 141914315 | I13: 141911459 | J13: 141914429 | K13: 141911676 | L13: 142002060 | M13: 141911583 | N13: 142003000 | O13: 141911590 | P13: 142002809 | Q13: 142002048 | R13: 141914835 | S13: 141914983 | T13: 141915705 | U13: 141915033 | V13: 141914796
B14: 141825574 | C14: 141825624 | D14: 141906871 | E14: 141911202 | F14: 141911428 | G14: 141911458 | H14: 141914316 | I14: 141911504 | J14: 141914431 | K14: 141914351 | L14: 142002061 | M14: 141911584 | N14: 142003001 | O14: 141911591 | P14: 142003677 | Q14: 142002051 | R14: 141914836 | S14: 141914984 | T14: 141915706 | U14: 142002236 | V14: 141914798
B15: 141825575 | C15: 141825625 | D15: 141906872 | E15: 141911204 | F15: 141911429 | G15: 141911460 | H15: 141914317 | I15: 141911505 | J15: 141914432 | K15: 141914356 | L15: 142002062 | M15: 141914486 | N15: 142003002 | O15: 141911592 | P15: 142003678 | Q15: 142002053 | R15: 141914837 | S15: 141914985 | T15: 141915708 | U15: 142003577 | V15: 141914799
B16: 141825576 | C16: 141825626 | D16: 141906873 | E16: 141911205 | F16: 141911430 | G16: 141911484 | H16: 141914318 | I16: 141911506 | J16: 141914433 | K16: 141914358 | L16: 142002063 | M16: 142002107 | N16: 142003003 | O16: 141911594 | P16: 142003679 | Q16: 142002056 | R16: 141914838 | S16: 141914986 | T16: 141915709 | U16: 142003578 | V16: 141914800
B17: 141825577 | C17: 141825627 | D17: 141906874 | E17: 141911206 | F17: 141911431 | G17: 141911485 | H17: 141914319 | I17: 141911509 | J17: 141914434 | K17: 141914359 | L17: 142002064 | M17: 142002108 | N17: 142003004 | O17: 141911595 | P17: 142003680 | Q17: 142002230 | R17: 141914839 | S17: 141914987 | T17: 141915711 | U17: 142003579 | V17: 141914801
B18: 141825578 | C18: 141825628 | D18: 141906875 | E18: 141911209 | F18: 141911432 | G18: 141911486 | H18: 141914320 | I18: 141911510 | J18: 141914436 | K18: 141914360 | L18: 142002065 | M18: 142002109 | N18: 142003005 | O18: 141911596 | P18: 142003681 | Q18: 142002445 | R18: 141914840 | S18: 141914988 | T18: 142001915 | U18: 142003580 | V18: 141915162
B19: 141825579 | C19: 141825629 | D19: 141906876 | E19: 141911210 | F19: 141911433 | G19: 141911491 | H19: 141914321 | I19: 141911512 | J19: 141914437 | K19: 141914361 | L19: 142002066 | M19: 142002110 | N19: 142003006 | O19: 141911597 | P19: 142003682 | Q19: 142003357 | R19: 141914841 | S19: 141914989 | T19: 142001916 | U19: 142003581 | V19: 141915163
B20: 141825580 | C20: 141825630 | D20: 141906877 | E20: 141911214 | F20: 141911434 | G20: 141911492 | H20: 141914322 | I20: 141914882 | J20: 141914438 | K20: 141914362 | L20: 142002067 | M20: 142002111 | N20: 142003007 | O20: 141911598 | P20: 142003683 | Q20: 142003358 | R20: 141914842 | S20: 141914990 | T20: 142001927 | U20: 142003582 | V20: 141915164
B21: 141825581 | C21: 141825631 | D21: 141906880 | E21: 141911215 | F21: 141911435 | G21: 141911493 | H21: 141914323 | I21: 142001867 | J21: 141914439 | K21: 141914363 | L21: 142002068 | M21: 142002112 | N21: 142003008 | O21: 141911599 | P21: 142003684 | Q21: 142003359 | R21: 141914843 | S21: 141914991 | T21: 142008915 | U21: 142003583 | V21: 141915165
B22: 141825582 | C22: 141825632 | D22: 141906881 | E22: 141911216 | F22: 141911436 | G22: 141911522 | H22: 141914324 | I22: 142001868 | J22: 141914440 | K22: 141914364 | L22: 142002069 | M22: 142002113 | N22: 142003009 | O22: 141911600 | P22: 142003685 | Q22: 142003360 | R22: 141914844 | S22: 141914992 | T22: 142008916 | U22: 142003584 | V22: 141915166
... B72: 141906140 | C72: 141911186 | D72: 141906934 | E72: 141911266 | F72: 141911508 | G72: 502003239 | H72: 142001557 | I72: 142001922 | J72: 142001999 | K72: 141914416 | L72: 501916058 | M72: 142003849 | N72: 501916112 | O72: 502003244 | P72: 142003735 | Q72: 142003412 | R72: 141914895 | S72: 141915045 | T72: 142008966 | U72: 142008348 | V72: 142002801
B73: 141906141 | C73: 141911188 | D73: 141906935 | E73: 141911267 | F73: 141911511 | H73: 142001558 | I73: 142001923 | J73: 142002000 | K73: 141914417 | L73: 501916059 | M73: 501821909 | N73: 501916113 | O73: 502003245 | P73: 142003736 | Q73: 142003413 | R73: 141914896 | S73: 141915046 | T73: 142008967 | U73: 142008349 | V73: 142002802
B74: 141906142 | C74: 141911189 | D74: 141906936 | E74: 141911268 | F74: 141911513 | H74: 142001559 | I74: 142001924 | J74: 142002001 | K74: 141914418 | L74: 501916060 | M74: 501916063 | N74: 501916114 | O74: 502003246 | P74: 142003737 | Q74: 142003414 | R74: 141914897 | S74: 141915047 | T74: 142008968 | U74: 142008350 | V74: 142002803
B75: 141906145 | C75: 141911190 | D75: 141906937 | E75: 141911269 | F75: 141911514 | H75: 142001560 | I75: 142001925 | J75: 142002002 | K75: 141914419 | L75: 501916061 | N75: 502003243 | O75: 502003247 | P75: 142003738 | Q75: 142003415 | R75: 141914898 | S75: 141915048 | T75: 142008969 | U75: 142008351 | V75: 142002804
B76: 141906146 | C76: 141911191 | D76: 141906938 | E76: 141911270 | F76: 141911515 | H76: 142001561 | I76: 142001926 | J76: 142002004 | K76: 141914420 | L76: 501916062 | P76: 142003739 | Q76: 142003416 | R76: 141914899 | S76: 141915049 | T76: 142008970 | U76: 142008352 | V76: 142002805
B77: 141906178 | C77: 141911192 | D77: 141906940 | E77: 141911271 | F77: 141911516 | H77: 142001562 | I77: 142001928 | J77: 142002005 | K77: 141914421 | L77: 502003092 | P77: 142003740 | Q77: 142003417 | R77: 141914900 | S77: 141915050 | T77: 142008971 | U77: 142008353 | V77: 142002806
B78: 141906179 | C78: 141911193 | D78: 141906941 | E78: 141911272 | F78: 141911517 | H78: 142001563 | I78: 142001929 | J78: 142002006 | K78: 141914422 | L78: 502003197 | P78: 142003741 | Q78: 142003418 | R78: 141914901 | S78: 141915051 | T78: 142008972 | U78: 142008354 | V78: 142003337
B79: 141906180 | C79: 141911194 | D79: 141906942 | E79: 141911273 | F79: 141911518 | H79: 142001564 | I79: 142001930 | J79: 142002007 | K79: 141914423 | L79: 502003243 | P79: 142003742 | Q79: 142003419 | R79: 141914902 | S79: 141915052 | T79: 142008973 | U79: 142008655 | V79: 142003338
B80: 141906181 | C80: 141911195 | D80: 141906943 | E80: 141911274 | F80: 141911519 | H80: 142001565 | I80: 142001931 | J80: 142002008 | K80: 141914424 | P80: 142003743 | Q80: 142003420 | R80: 141914903 | S80: 141915053 | T80: 142008974 | U80: 142008656 | V80: 142003339
B81: 141906182 | C81: 141911196 | D81: 141906944 | E81: 141911275 | F81: 141911520 | H81: 142001566 | I81: 142001933 | J81: 142002009 | K81: 141914425 | P81: 142003744 | Q81: 142003421 | R81: 141914904 | S81: 141915054 | T81: 142008975 | U81: 142008657 | V81: 142003340
B82: 141906183 | C82: 141911197 | D82: 141906945 | E82: 141911276 | F82: 141911521 | H82: 142001567 | I82: 142001934 | J82: 142002010 | K82: 141914427 | P82: 142003745 | Q82: 142003422 | R82: 141914905 | S82: 141915055 | T82: 142008976 | U82: 142008658 | V82: 142003341
B83: 141906184 | C83: 141911198 | D83: 141906946 | E83: 141911277 | F83: 141911523 | H83: 142001568 | I83: 142001935 | J83: 142002011 | K83: 141914435 | P83: 142003746 | Q83: 142003423 | R83: 141914906 | S83: 141915056 | T83: 142008977 | U83: 142008659 | V83: 142003342
B84: 141906185 | C84: 141911203 | D84: 141906947 | E84: 141911279 | F84: 141911524 | H84: 142001569 | I84: 142001937 | J84: 142002012 | K84: 141914442 | P84: 142003747 | Q84: 142003424 | R84: 141914907 | S84: 141915057 | T84: 142008978 | U84: 142008660 | V84: 142003343
B85: 141906186 | C85: 141911207 | D85: 141906948 | E85: 141911280 | F85: 141911525 | H85: 142001570 | I85: 142001938 | J85: 142002013 | K85: 141914443 | P85: 142003748 | Q85: 142003425 | R85: 141914908 | S85: 141915058 | T85: 142008979 | U85: 142008661 | V85: 142003344
B86: 141906187 | C86: 141911208 | D86: 141906949 | E86: 141911281 | F86: 141911526 | H86: 142001571 | I86: 142001939 | J86: 142002014 | K86: 141914444 | P86: 142003749 | Q86: 142003426 | R86: 141914909 | S86: 141915059 | T86: 142008980 | U86: 142008662 | V86: 142003345
B87: 141911278 | C87: 141911211 | D87: 141906950 | E87: 141911282 | F87: 141911527 | H87: 142001572 | I87: 142001940 | J87: 142002015 | K87: 141914445 | P87: 142003750 | Q87: 142003427 | R87: 141914910 | S87: 141915060 | T87: 142008981 | U87: 142008663 | V87: 142003346
B88: 141911418 | C88: 141911212 | D88: 141906951 | E88: 141911283 | F88: 141911529 | H88: 142001573 | I88: 142001941 | J88: 142002016 | K88: 141914446 | P88: 142003751 | Q88: 142003428 | R88: 141914911 | S88: 141915061 | T88: 142008982 | U88: 142008664 | V88: 142003347
B89: 141911423 | C89: 141911213 | D89: 141906952 | E89: 141911284 | F89: 141911530 | H89: 142001574 | I89: 142001942 | J89: 142002017 | K89: 141914447 | P89: 142003752 | Q89: 142003429 | R89: 141914912 | S89: 141915062 | T89: 142008983 | U89: 142008665 | V89: 142003348
...

Sheet Hoja5

Sheet Hoja4

Sheet RUTA16
A2: 130 | B2: 102 | C2: 233 | D2: 61 | E2: 66 | F2: =SUM(A2:E2) -> 592
A3: Ruta16 | B3: Ruta16 | C3: Ruta16 | D3: Ruta16 | E3: Ruta16
A4: 1438 | B4: 1509 | C4: 1026 | D4: 1439 | E4: 1147
A5: 4621606418 | B5: 4621502009 | C5: 4621936100 | E5: 4622004203
A6: 141825620 | B6: 141906147 | C6: 141825641 | D6: 141911579 | E6: 142002997
A7: 141825621 | B7: 141906868 | C7: 141911187 | D7: 141911580 | E7: 142002998
A8: 141825622 | B8: 141906869 | C8: 141911199 | D8: 141911581 | E8: 142002999
A9: 141825623 | B9: 141906870 | C9: 141911200 | D9: 141911583 | E9: 142003000
A10: 141825624 | B10: 141906871 | C10: 141911201 | D10: 141911584 | E10: 142003001
A11: 141825625 | B11: 141906872 | C11: 141911202 | D11: 142002107 | E11: 142003002
A12: 141825626 | B12: 141906873 | C12: 141911204 | D12: 142002108 | E12: 142003003
A13: 141825627 | B13: 141906874 | C13: 141911205 | D13: 142002109 | E13: 142003004
A14: 141825628 | B14: 141906875 | C14: 141911206 | D14: 142002110 | E14: 142003005
A15: 141825629 | B15: 141906876 | C15: 141911209 | D15: 142002111 | E15: 142003006
A16: 141825630 | B16: 141906877 | C16: 141911210 | D16: 142002112 | E16: 142003007
A17: 141825631 | B17: 141906880 | C17: 141911214 | D17: 142002113 | E17: 142003008
... A66: 141906884 | B66: 141906932 | C66: 141911263 | D66: 501916063 | E66: 501916110
A67: 141906885 | B67: 141906933 | C67: 141911264
A68: 141911184 | B68: 141906934 | C68: 141911265
A69: 141911185 | B69: 141906935 | C69: 141911266
A70: 141911186 | B70: 141906936 | C70: 141911267
A71: 141911188 | B71: 141906937 | C71: 141911268
A72: 141911189 | B72: 141906938 | C72: 141911269
A73: 141911190 | B73: 141906939 | C73: 141911270
A74: 141911191 | B74: 141906940 | C74: 141911271
A75: 141911192 | B75: 141906941 | C75: 141911272
A76: 141911193 | B76: 141906942 | C76: 141911273
A77: 141911194 | B77: 141906943 | C77: 141911274
A78: 141911195 | B78: 141906944 | C78: 141911275
... A107: 141911393 | B107: 501821934 | C107: 141911315
A108: 141911587 | C108: 141911316
A109: 142002163 | C109: 141911317
A110: 501627056 | C110: 141911318
A111: 501627059 | C111: 141911319
A112: 501627060 | C112: 141911320
A113: 501627063 | C113: 141911321
A114: 501821790 | C114: 141911322
A115: 501821793 | C115: 141911323
A116: 501821895 | C116: 141911324
A117: 501821912 | C117: 141911325
...

Sheet RUTA15
D2: ver
B3: =141 -> 141 | C3: =37 -> 37 | D3: =103 -> 103 | E3: =106 -> 106 | F3: 243 | G3: 91 | H3: =67 -> 67 | I3: =SUM(B3:H3)-D3 -> 685
B4: Ruta15 | C4: Ruta15 | D4: Ruta15 | E4: Ruta15 | F4: Ruta15 | G4: Ruta15 | H4: Ruta15
B5: 1279 | C5: 1386 | D5: 1579 | E5: 1405 | F5: 1017 | G5: 1608 | H5: 1025
B6: 4621838101 | C6: 4622004200 | D6: 4622004210 | E6: 4622004205 | F6: 4621936122 | G6: 4622004173 | H6: 4622004201
B7: 141911424 | C7: 141911609 | D7: 141911451 | E7: 141914312 | F7: 141911564 | G7: 141914426 | H7: 142002057
B8: 141911425 | C8: 141911610 | D8: 141911452 | E8: 141914313 | F8: 141911658 | G8: 142001862 | H8: 142002058
B9: 141911426 | C9: 141911624 | D9: 141911453 | E9: 141914314 | F9: 141914351 | G9: 142001863 | H9: 142002059
B10: 141911427 | C10: 141911625 | D10: 141911459 | E10: 141914315 | F10: 141914356 | G10: 142001864 | H10: 142002060
B11: 141911428 | C11: 141911626 | D11: 141911504 | E11: 141914316 | F11: 141914358 | G11: 142001866 | H11: 142002061
B12: 141911429 | C12: 141911627 | D12: 141911505 | E12: 141914317 | F12: 141914359 | G12: 142001960 | H12: 142002062
B13: 141911430 | C13: 141911628 | D13: 141911506 | E13: 141914318 | F13: 141914360 | G13: 142001961 | H13: 142002063
B14: 141911431 | C14: 141911629 | D14: 141911509 | E14: 141914319 | F14: 141914361 | G14: 142001962 | H14: 142002064
B15: 141911432 | C15: 141911630 | D15: 141911510 | E15: 141914320 | F15: 141914362 | G15: 142001963 | H15: 142002065
B16: 141911433 | C16: 141911631 | D16: 141911512 | E16: 141914321 | F16: 141914363 | G16: 142001964 | H16: 142002066
... B43: 141911464 | C43: 501821893 | D43: 142001896 | E43: 141914348 | F43: 141914390 | G43: 142001992 | H43: 142002093
B44: 141911465 | D44: 142001897 | E44: 141914349 | F44: 141914391 | G44: 142001993 | H44: 142002094
B45: 141911466 | D45: 142001898 | E45: 141914350 | F45: 141914392 | G45: 142001994 | H45: 142002095
B46: 141911467 | D46: 142001899 | E46: 141914352 | F46: 141914393 | G46: 142001995 | H46: 142002096
B47: 141911468 | D47: 142001900 | E47: 141914353 | F47: 141914394 | G47: 142001996 | H47: 142002097
B48: 141911469 | D48: 142001901 | E48: 141914354 | F48: 141914395 | G48: 142001997 | H48: 142002098
B49: 141911470 | D49: 142001902 | E49: 141914355 | F49: 141914396 | G49: 142001998 | H49: 142002099
B50: 141911471 | D50: 142001903 | E50: 141914357 | F50: 141914397 | G50: 142001999 | H50: 142002100
B51: 141911472 | D51: 142001904 | E51: 142001537 | F51: 141914398 | G51: 142002000 | H51: 142002101
B52: 141911473 | D52: 142001905 | E52: 142001538 | F52: 141914399 | G52: 142002001 | H52: 142002102
B53: 141911474 | D53: 142001906 | E53: 142001539 | F53: 141914400 | G53: 142002002 | H53: 142002103
B54: 141911475 | D54: 142001907 | E54: 142001540 | F54: 141914401 | G54: 142002003 | H54: 142002104
B55: 141911476 | D55: 142001908 | E55: 142001541 | F55: 141914402 | G55: 142002004 | H55: 142002105
... B75: 141911497 | D75: 142001928 | E75: 142001561 | F75: 141914422 | G75: 142002024 | H75: 502003092
B76: 141911498 | D76: 142001929 | E76: 142001562 | F76: 141914423 | G76: 142002025
B77: 141911499 | D77: 142001930 | E77: 142001563 | F77: 141914424 | G77: 142002026
B78: 141911500 | D78: 142001931 | E78: 142001564 | F78: 141914425 | G78: 142002027
B79: 141911501 | D79: 142001932 | E79: 142001565 | F79: 141914427 | G79: 142002028
B80: 141911502 | D80: 142001933 | E80: 142001566 | F80: 141914428 | G80: 142002029
B81: 141911503 | D81: 142001934 | E81: 142001567 | F81: 141914429 | G81: 142002030
B82: 141911507 | D82: 142001935 | E82: 142001568 | F82: 141914430 | G82: 142002031
B83: 141911508 | D83: 142001936 | E83: 142001569 | F83: 141914431 | G83: 142002032
B84: 141911511 | D84: 142001937 | E84: 142001570 | F84: 141914432 | G84: 142002033
B85: 141911513 | D85: 142001938 | E85: 142001571 | F85: 141914433 | G85: 142002034
B86: 141911514 | D86: 142001939 | E86: 142001572 | F86: 141914434 | G86: 142002035
...

Sheet RUTA 14
A3: =103 -> 103 | B3: 66 | C3: 178 | D3: 230 | E3: 104 | F3: 275 | H3: =SUM(A3:G3) -> 956 | K3: B. Voluntarios Y Venezuela | M3: 104
A4: Ruta15 | B4: Ruta 16/5 | K4: 36-set6-B. Voluntarios Y R. Escalada | M4: 275
A5: 1579 | B5: 1080 | C5: 1290 | D5: 1005 | E5: 1006
A6: 4622004210 | B6: 4622050030 | C6: 141911586 | D6: 141906939
A7: 141911451 | B7: 141911585 | C7: 142002808 | D7: 142002047
A8: 141911452 | B8: 141911588 | C8: 142002809 | D8: 142002048
A9: 141911453 | B9: 141911589 | C9: 142003677 | D9: 142002051
A10: 141911459 | B10: 141911590 | C10: 142003678 | D10: 142002053
A11: 141911504 | B11: 141911591 | C11: 142003679 | D11: 142002056
A12: 141911505 | B12: 141911592 | C12: 142003680 | D12: 142003357
A13: 141911506 | B13: 141911594 | C13: 142003681 | D13: 142003358
A14: 141911509 | B14: 141911595 | C14: 142003682 | D14: 142003359
A15: 141911510 | B15: 141911596 | C15: 142003683 | D15: 142003360
A16: 141911512 | B16: 141911597 | C16: 142003684 | D16: 142003361
A17: 142001867 | B17: 141911598 | C17: 142003685 | D17: 142003362
... A72: 142001925 | B72: 502003246 | C72: 142003740 | D72: 142003419
A73: 142001926 | D73: 142003420
A74: 142001927 | D74: 142003421
A75: 142001928 | D75: 142003422
A76: 142001929 | D76: 142003423
A77: 142001930 | D77: 142003424
A78: 142001931 | D78: 142003425
A79: 142001932 | D79: 142003426
A80: 142001933 | D80: 142003427
A81: 142001934 | D81: 142003428
A82: 142001935 | D82: 142003429
A83: 142001936 | D83: 142003430
A84: 142001937 | D84: 142003431
... A109: 501916045 | D109: 142003456
D110: 142003457
D111: 142003458
D112: 142003459
D113: 142003460
D114: 142003461
D115: 142003462
D116: 142003463
D117: 142003464
D118: 142003465
D119: 142003466
D120: 142003467
...

Sheet RUTA 17
K2: ZONA 2
L4: concentrador | M4: set | N4: nodo | O4: usuarios
L5: 1 | M5: 357 | N5: 365 | O5: 222 | P5: España y puerredon | Q5: 1
L6: 2 | M6: 10 | N6: 382 | O6: 154 | P6: Croacia y pelliza | Q6: 1
L7: 3 | M7: 312 | N7: 903 | O7: 157 | P7: Barrio pancho sierra | Q7: 1
L8: 4 | M8: 61 | N8: 1228 | O8: 45 | P8: Soldado argentino y Uruguay | Q8: 1
L9: 5 | M9: 16 | N9: 387 | O9: 18 | P9: Jose hernandez y Pancho sierra
L10: 6 | M10: 500 | N10: 376620 | O10: 20 | P10: Soldado argentino y cortazar
L11: 7 | M11: 522 | N11: 61679951 | O11: 99 | P11: 52-set 522-Agente Cepeda Y Pelliza
L12: 8 | M12: 363 | N12: 547 | O12: 32 | P12: L.Arufe y Uruguay
L13: 9 | M13: ver
L14: 10 | M14: ver
N15: Total | O15: =SUM(O5:O12) -> 747
L17: Materiales | M17: Cant | N17: Precio unit.
L18: concentrador | M18: 10 | N18: 1035 | O18: =M18*N18 -> 10350
L19: Trifa | M19: =M21*0.1 -> 74.7 | N19: 228 | O19: =M19*N19 -> 17031.6
L20: Mono | M20: =M21*0.9 -> 672.3 | N20: 118 | O20: =M20*N20 -> 79331.4
L21: medidores | M21: 747
N24: Total | O24: =SUM(O18:O23) -> 106713 | P24: dolares(BNA 70.25 20/05/28)
P25: 70.25 | Q25: dólar
N26: Total | O26: =O24*P25 -> 7496588.2 | P26: Pesos

Sheet Hoja3
A1: SET | B1: Medidor | C1: Estado | D1: ult comunicación | E1: usuario | F1: observacion | G1: Trabajo
A2: 438 | B2: 141825649 | C2: PF | D2: 44160.545 | E2: NOVIK MARIA CRISTINA | F2: activo | G2: En el SET 17
B3: 141906167 | C3: PF | D3: 44095.578 | E3: BARRIENTOS KARINA B | F3: activo | G3: cambia medidor
B4: 501821933 | C4: PF | D4: 43907.639 | E4: MERCE JOSE, ROBERTO C.,EDUARDO J. | F4: se saco | G4: se saco
A6: 26 | B6: 141911406 | C6: PF | D6: 44098.544 | E6: No figura GIS | F6: se saco | G6: se saco
B7: 141911576 | C7: PF | D7: 44263.796 | E7: BARRIOS AZUL ANAHI | F7: activo | G7: En otro trafo
B8: 141911577 | C8: PF | D8: 44263.77 | E8: FANUCCE MARIA EUGENIA | F8: activo | G8: En otro trafo
A10: 509 | B10: 141906892 | C10: PF | D10: 43906.384 | E10: NO esta en el GIS | F10: se saco | G10: se saco
A12: 147 | B12: 142002130 | C12: PF | D12: 44250.522 | E12: DE OLIVEIRA ZARDIN DIEGO ARIEL | G12: accidente pilares
B13: 142002132 | C13: PF | D13: 44250.522 | E13: ALMADA ESTEFANIA YAMILA | G13: accidente pilares
B14: 142002133 | C14: PF | D14: 44250.522 | E14: GUTIERREZ JONATAN | G14: accidente pilares
A16: 439 | B16: 142002130 | C16: PF | D16: 44250.522
B17: 142002132 | C17: PF | D17: 44250.522
B18: 142002133 | C18: PF | D18: 44250.522
A20: 25 | B20: 501916052 | E20: GARDINALI NESTOR ORLANDO

Sheet Hoja2
A2: Ruta | B2: 1570 | C2: 1438 | D2: 1509 | E2: 1026 | F2: 1279 | G2: 1386 | H2: 1579 | I2: 1405 | J2: 1017 | K2: 1608 | L2: 1025 | M2: 1439 | N2: 1147
A3: Concentradores | B3: 4621502023 | C3: 4621606418 | D3: 4621502009 | E3: 4621936100 | F3: 4621838101 | G3: 4622004200 | H3: 4622004210 | I3: 4622004205 | J3: 4621936122 | K3: 4622004173 | L3: 4622004201 | M3: 4621936101 | T3: falta | U3: lo que hay
B4: =COUNT('Hoja1-1'!B10:B104) -> 95 | C4: =COUNT('Hoja1-1'!C10:C112) -> 103 | D4: =COUNT('Hoja1-1'!D10:D106) -> 97 | E4: =COUNT('Hoja1-1'!E10:E217) -> 208 | F4: =COUNT('Hoja1-1'!F10:F146) -> 115 | G4: =COUNT('Hoja1-1'!G10:G45) -> 36 | H4: =COUNT('Hoja1-1'!I10:I109) -> 100 | I4: =COUNT('Hoja1-1'!H10:H105) -> 96 | J4: 213 | K4: =COUNT('Hoja1-1'!J10:J98) -> 89 | L4: =COUNT('Hoja1-1'!L10:L59) -> 50 | M4: =COUNT('Hoja1-1'!M11:M68) -> 58 | O4: =SUM(B4:N4) -> 1260 | Q4: 230 | R4: 2250 | S4: =R4+Q4 -> 2480 | T4: 300 | U4: =S4-T4 -> 2180 | W4: =U4-O4 -> 920
B5: =COUNT('Hoja1-1'!B105:B114) -> 10 | C5: =COUNT('Hoja1-1'!C113:C136) -> 24 | D5: =COUNT('Hoja1-1'!D107:D110) -> 4 | E5: =COUNT('Hoja1-1'!E218:E235) -> 18 | F5: =COUNT('Hoja1-1'!F147:F150) -> 0 | G5: =COUNT('Hoja1-1'!G46) -> 1 | H5: =COUNT('Hoja1-1'!I110:I112) -> 3 | I5: =COUNT('Hoja1-1'!H106:H115) -> 10 | J5: =COUNT('Hoja1-1'!K223:K252) -> 10 | K5: =COUNT('Hoja1-1'!J99:J100) -> 2 | L5: =COUNT('Hoja1-1'!L60:L76) -> 17 | M5: =COUNT('Hoja1-1'!M69:M70) -> 2 | O5: =SUM(B5:N5) -> 101 | Q5: 20 | R5: 250 | S5: =R5+Q5 -> 270 | T5: 35 | U5: =S5-T5 -> 235 | W5: =U5-O5 -> 134
B6: =SUM(B4:B5) -> 105 | C6: =SUM(C4:C5) -> 127 | D6: =SUM(D4:D5) -> 101 | E6: =SUM(E4:E5) -> 226 | F6: =SUM(F4:F5) -> 115 | G6: =SUM(G4:G5) -> 37 | H6: =SUM(H4:H5) -> 103 | I6: =SUM(I4:I5) -> 106 | ... M6: =SUM(M4:M5) -> 60 | O6: =SUM(O4:O5) -> 1361
